<?xml version="1.0"?>
<robot name="test_robot">
  <link name="link1">
    <visual>
        <geometry>
            <cylinder length="0.6" radius="0.2" />
        </geometry>
    </visual>
  </link>
  <link name="link2" />
  <link name="link3" />
  <link name="link4" />

  <joint name="joint1" type="continuous" >
    <parent link="link1" />
    <child link="link2" />
    <origin xyz=".5 .3 .0.7" rpy="0 0 0" />
  </joint>

  <joint name="joint2" type="continuous">
    <parent link="link1"/>
    <child link="link3"/>
    <origin xyz=".5 .3 .0.7" rpy="0 0 0" />
  </joint>

  <joint name="joint3" type="continuous" >
    <parent link="link3" />
    <child link="link4" />
    <origin xyz=".5 .3 .0.7" rpy="0 0 0" />
  </joint>
</robot>
